{"uid":"300584cdf59c07fb","name":"test_fixed_deposit_calculator","fullName":"tests.data_driven_test.test_excel_data#test_fixed_deposit_calculator","historyId":"3118f0ca324fd73b92491c40e8ddfb94","time":{"start":1752786041510,"stop":1752786041510,"duration":0},"status":"broken","statusMessage":"selenium.common.exceptions.SessionNotCreatedException: Message: session not created: probably user data directory is already in use, please specify a unique value for --user-data-dir argument, or don't use --user-data-dir\nStacktrace:\n#0 0x55ef7b66723a <unknown>\n#1 0x55ef7b111ab0 <unknown>\n#2 0x55ef7b14c8ac <unknown>\n#3 0x55ef7b147307 <unknown>\n#4 0x55ef7b197696 <unknown>\n#5 0x55ef7b196d56 <unknown>\n#6 0x55ef7b188f73 <unknown>\n#7 0x55ef7b155aeb <unknown>\n#8 0x55ef7b156751 <unknown>\n#9 0x55ef7b62bb4b <unknown>\n#10 0x55ef7b62f929 <unknown>\n#11 0x55ef7b612929 <unknown>\n#12 0x55ef7b6304e8 <unknown>\n#13 0x55ef7b5f70df <unknown>\n#14 0x55ef7b6548e8 <unknown>\n#15 0x55ef7b654ac6 <unknown>\n#16 0x55ef7b666556 <unknown>\n#17 0x7fc45c09caa4 <unknown>\n#18 0x7fc45c129c3c <unknown>","statusTrace":"conftest.py:149: in setup_teardown\n    driver = browser_manager.start_browser()\nutils/browser_manager.py:69: in start_browser\n    self.driver = webdriver.Chrome(options=options)\n/opt/hostedtoolcache/Python/3.10.18/x64/lib/python3.10/site-packages/selenium/webdriver/chrome/webdriver.py:47: in __init__\n    super().__init__(\n/opt/hostedtoolcache/Python/3.10.18/x64/lib/python3.10/site-packages/selenium/webdriver/chromium/webdriver.py:69: in __init__\n    super().__init__(command_executor=executor, options=options)\n/opt/hostedtoolcache/Python/3.10.18/x64/lib/python3.10/site-packages/selenium/webdriver/remote/webdriver.py:257: in __init__\n    self.start_session(capabilities)\n/opt/hostedtoolcache/Python/3.10.18/x64/lib/python3.10/site-packages/selenium/webdriver/remote/webdriver.py:356: in start_session\n    response = self.execute(Command.NEW_SESSION, caps)[\"value\"]\n/opt/hostedtoolcache/Python/3.10.18/x64/lib/python3.10/site-packages/selenium/webdriver/remote/webdriver.py:447: in execute\n    self.error_handler.check_response(response)\n/opt/hostedtoolcache/Python/3.10.18/x64/lib/python3.10/site-packages/selenium/webdriver/remote/errorhandler.py:232: in check_response\n    raise exception_class(message, screen, stacktrace)\nE   selenium.common.exceptions.SessionNotCreatedException: Message: session not created: probably user data directory is already in use, please specify a unique value for --user-data-dir argument, or don't use --user-data-dir\nE   Stacktrace:\nE   #0 0x55ef7b66723a <unknown>\nE   #1 0x55ef7b111ab0 <unknown>\nE   #2 0x55ef7b14c8ac <unknown>\nE   #3 0x55ef7b147307 <unknown>\nE   #4 0x55ef7b197696 <unknown>\nE   #5 0x55ef7b196d56 <unknown>\nE   #6 0x55ef7b188f73 <unknown>\nE   #7 0x55ef7b155aeb <unknown>\nE   #8 0x55ef7b156751 <unknown>\nE   #9 0x55ef7b62bb4b <unknown>\nE   #10 0x55ef7b62f929 <unknown>\nE   #11 0x55ef7b612929 <unknown>\nE   #12 0x55ef7b6304e8 <unknown>\nE   #13 0x55ef7b5f70df <unknown>\nE   #14 0x55ef7b6548e8 <unknown>\nE   #15 0x55ef7b654ac6 <unknown>\nE   #16 0x55ef7b666556 <unknown>\nE   #17 0x7fc45c09caa4 <unknown>\nE   #18 0x7fc45c129c3c <unknown>","flaky":false,"newFailed":false,"newBroken":false,"newPassed":false,"retriesCount":0,"retriesStatusChange":false,"beforeStages":[{"name":"setup_teardown","time":{"start":1752786041510,"stop":1752786041710,"duration":200},"status":"broken","statusMessage":"selenium.common.exceptions.SessionNotCreatedException: Message: session not created: probably user data directory is already in use, please specify a unique value for --user-data-dir argument, or don't use --user-data-dir\nStacktrace:\n#0 0x55ef7b66723a <unknown>\n#1 0x55ef7b111ab0 <unknown>\n#2 0x55ef7b14c8ac <unknown>\n#3 0x55ef7b147307 <unknown>\n#4 0x55ef7b197696 <unknown>\n#5 0x55ef7b196d56 <unknown>\n#6 0x55ef7b188f73 <unknown>\n#7 0x55ef7b155aeb <unknown>\n#8 0x55ef7b156751 <unknown>\n#9 0x55ef7b62bb4b <unknown>\n#10 0x55ef7b62f929 <unknown>\n#11 0x55ef7b612929 <unknown>\n#12 0x55ef7b6304e8 <unknown>\n#13 0x55ef7b5f70df <unknown>\n#14 0x55ef7b6548e8 <unknown>\n#15 0x55ef7b654ac6 <unknown>\n#16 0x55ef7b666556 <unknown>\n#17 0x7fc45c09caa4 <unknown>\n#18 0x7fc45c129c3c <unknown>\n\n","statusTrace":"  File \"/opt/hostedtoolcache/Python/3.10.18/x64/lib/python3.10/site-packages/pluggy/_callers.py\", line 38, in run_old_style_hookwrapper\n    res = yield\n  File \"/opt/hostedtoolcache/Python/3.10.18/x64/lib/python3.10/site-packages/pluggy/_callers.py\", line 139, in _multicall\n    teardown.throw(exception)\n  File \"/opt/hostedtoolcache/Python/3.10.18/x64/lib/python3.10/site-packages/_pytest/setuponly.py\", line 36, in pytest_fixture_setup\n    return (yield)\n  File \"/opt/hostedtoolcache/Python/3.10.18/x64/lib/python3.10/site-packages/pluggy/_callers.py\", line 121, in _multicall\n    res = hook_impl.function(*args)\n  File \"/opt/hostedtoolcache/Python/3.10.18/x64/lib/python3.10/site-packages/_pytest/fixtures.py\", line 1195, in pytest_fixture_setup\n    result = call_fixture_func(fixturefunc, request, kwargs)\n  File \"/opt/hostedtoolcache/Python/3.10.18/x64/lib/python3.10/site-packages/_pytest/fixtures.py\", line 922, in call_fixture_func\n    fixture_result = next(generator)\n  File \"/home/runner/work/selenium_pytest/selenium_pytest/conftest.py\", line 149, in setup_teardown\n    driver = browser_manager.start_browser()\n  File \"/home/runner/work/selenium_pytest/selenium_pytest/utils/browser_manager.py\", line 69, in start_browser\n    self.driver = webdriver.Chrome(options=options)\n  File \"/opt/hostedtoolcache/Python/3.10.18/x64/lib/python3.10/site-packages/selenium/webdriver/chrome/webdriver.py\", line 47, in __init__\n    super().__init__(\n  File \"/opt/hostedtoolcache/Python/3.10.18/x64/lib/python3.10/site-packages/selenium/webdriver/chromium/webdriver.py\", line 69, in __init__\n    super().__init__(command_executor=executor, options=options)\n  File \"/opt/hostedtoolcache/Python/3.10.18/x64/lib/python3.10/site-packages/selenium/webdriver/remote/webdriver.py\", line 257, in __init__\n    self.start_session(capabilities)\n  File \"/opt/hostedtoolcache/Python/3.10.18/x64/lib/python3.10/site-packages/selenium/webdriver/remote/webdriver.py\", line 356, in start_session\n    response = self.execute(Command.NEW_SESSION, caps)[\"value\"]\n  File \"/opt/hostedtoolcache/Python/3.10.18/x64/lib/python3.10/site-packages/selenium/webdriver/remote/webdriver.py\", line 447, in execute\n    self.error_handler.check_response(response)\n  File \"/opt/hostedtoolcache/Python/3.10.18/x64/lib/python3.10/site-packages/selenium/webdriver/remote/errorhandler.py\", line 232, in check_response\n    raise exception_class(message, screen, stacktrace)\n","steps":[],"attachments":[],"parameters":[],"shouldDisplayMessage":true,"stepsCount":0,"attachmentsCount":0,"hasContent":true}],"testStage":{"status":"broken","statusMessage":"selenium.common.exceptions.SessionNotCreatedException: Message: session not created: probably user data directory is already in use, please specify a unique value for --user-data-dir argument, or don't use --user-data-dir\nStacktrace:\n#0 0x55ef7b66723a <unknown>\n#1 0x55ef7b111ab0 <unknown>\n#2 0x55ef7b14c8ac <unknown>\n#3 0x55ef7b147307 <unknown>\n#4 0x55ef7b197696 <unknown>\n#5 0x55ef7b196d56 <unknown>\n#6 0x55ef7b188f73 <unknown>\n#7 0x55ef7b155aeb <unknown>\n#8 0x55ef7b156751 <unknown>\n#9 0x55ef7b62bb4b <unknown>\n#10 0x55ef7b62f929 <unknown>\n#11 0x55ef7b612929 <unknown>\n#12 0x55ef7b6304e8 <unknown>\n#13 0x55ef7b5f70df <unknown>\n#14 0x55ef7b6548e8 <unknown>\n#15 0x55ef7b654ac6 <unknown>\n#16 0x55ef7b666556 <unknown>\n#17 0x7fc45c09caa4 <unknown>\n#18 0x7fc45c129c3c <unknown>","statusTrace":"conftest.py:149: in setup_teardown\n    driver = browser_manager.start_browser()\nutils/browser_manager.py:69: in start_browser\n    self.driver = webdriver.Chrome(options=options)\n/opt/hostedtoolcache/Python/3.10.18/x64/lib/python3.10/site-packages/selenium/webdriver/chrome/webdriver.py:47: in __init__\n    super().__init__(\n/opt/hostedtoolcache/Python/3.10.18/x64/lib/python3.10/site-packages/selenium/webdriver/chromium/webdriver.py:69: in __init__\n    super().__init__(command_executor=executor, options=options)\n/opt/hostedtoolcache/Python/3.10.18/x64/lib/python3.10/site-packages/selenium/webdriver/remote/webdriver.py:257: in __init__\n    self.start_session(capabilities)\n/opt/hostedtoolcache/Python/3.10.18/x64/lib/python3.10/site-packages/selenium/webdriver/remote/webdriver.py:356: in start_session\n    response = self.execute(Command.NEW_SESSION, caps)[\"value\"]\n/opt/hostedtoolcache/Python/3.10.18/x64/lib/python3.10/site-packages/selenium/webdriver/remote/webdriver.py:447: in execute\n    self.error_handler.check_response(response)\n/opt/hostedtoolcache/Python/3.10.18/x64/lib/python3.10/site-packages/selenium/webdriver/remote/errorhandler.py:232: in check_response\n    raise exception_class(message, screen, stacktrace)\nE   selenium.common.exceptions.SessionNotCreatedException: Message: session not created: probably user data directory is already in use, please specify a unique value for --user-data-dir argument, or don't use --user-data-dir\nE   Stacktrace:\nE   #0 0x55ef7b66723a <unknown>\nE   #1 0x55ef7b111ab0 <unknown>\nE   #2 0x55ef7b14c8ac <unknown>\nE   #3 0x55ef7b147307 <unknown>\nE   #4 0x55ef7b197696 <unknown>\nE   #5 0x55ef7b196d56 <unknown>\nE   #6 0x55ef7b188f73 <unknown>\nE   #7 0x55ef7b155aeb <unknown>\nE   #8 0x55ef7b156751 <unknown>\nE   #9 0x55ef7b62bb4b <unknown>\nE   #10 0x55ef7b62f929 <unknown>\nE   #11 0x55ef7b612929 <unknown>\nE   #12 0x55ef7b6304e8 <unknown>\nE   #13 0x55ef7b5f70df <unknown>\nE   #14 0x55ef7b6548e8 <unknown>\nE   #15 0x55ef7b654ac6 <unknown>\nE   #16 0x55ef7b666556 <unknown>\nE   #17 0x7fc45c09caa4 <unknown>\nE   #18 0x7fc45c129c3c <unknown>","steps":[],"attachments":[{"uid":"27551de49e1a5bf","name":"test_log","source":"27551de49e1a5bf.txt","type":"text/plain","size":1650}],"parameters":[],"shouldDisplayMessage":true,"stepsCount":0,"attachmentsCount":1,"hasContent":true},"afterStages":[],"labels":[{"name":"parentSuite","value":"tests.data_driven_test"},{"name":"suite","value":"test_excel_data"},{"name":"host","value":"pkrvmq0rgcvqdmg"},{"name":"thread","value":"2754-MainThread"},{"name":"framework","value":"pytest"},{"name":"language","value":"cpython3"},{"name":"package","value":"tests.data_driven_test.test_excel_data"},{"name":"resultFormat","value":"allure2"}],"parameters":[],"links":[],"hidden":false,"retry":false,"extra":{"severity":"normal","retries":[],"categories":[{"name":"Test defects","matchedStatuses":[],"flaky":false}],"tags":[]},"source":"300584cdf59c07fb.json","parameterValues":[]}